<sdf version='1.4'>
  <world name='default'>
    <light name='sun' type='directional'>
      <cast_shadows>1</cast_shadows>
      <pose>0 0 10 0 -0 0</pose>
      <diffuse>0.8 0.8 0.8 1</diffuse>
      <specular>0.2 0.2 0.2 1</specular>
      <attenuation>
        <range>1000</range>
        <constant>0.9</constant>
        <linear>0.01</linear>
        <quadratic>0.001</quadratic>
      </attenuation>
      <direction>-0.5 0.1 -0.9</direction>
    </light>
    <model name='ground_plane'>
      <static>1</static>
      <link name='link'>
        <collision name='collision'>
          <geometry>
            <plane>
              <normal>0 0 1</normal>
              <size>100 100</size>
            </plane>
          </geometry>
          <surface>
            <friction>
              <ode>
                <mu>100</mu>
                <mu2>50</mu2>
              </ode>
            </friction>
            <bounce/>
            <contact>
              <ode/>
            </contact>
          </surface>
          <max_contacts>10</max_contacts>
        </collision>
        <visual name='visual'>
          <cast_shadows>0</cast_shadows>
          <geometry>
            <plane>
              <normal>0 0 1</normal>
              <size>100 100</size>
            </plane>
          </geometry>
          <material>
            <script>
              <uri>file://media/materials/scripts/gazebo.material</uri>
              <name>Gazebo/Grey</name>
            </script>
          </material>
        </visual>
        <velocity_decay>
          <linear>0</linear>
          <angular>0</angular>
        </velocity_decay>
        <self_collide>0</self_collide>
        <kinematic>0</kinematic>
        <gravity>1</gravity>
      </link>
    </model>
    <physics type='ode'>
      <max_step_size>0.001</max_step_size>
      <real_time_factor>1</real_time_factor>
      <real_time_update_rate>1000</real_time_update_rate>
      <gravity>0 0 -9.8</gravity>
    </physics>
    <scene>
      <ambient>0.4 0.4 0.4 1</ambient>
      <background>0.7 0.7 0.7 1</background>
      <shadows>1</shadows>
    </scene>
    <spherical_coordinates>
      <surface_model>EARTH_WGS84</surface_model>
      <latitude_deg>0</latitude_deg>
      <longitude_deg>0</longitude_deg>
      <elevation>0</elevation>
      <heading_deg>0</heading_deg>
    </spherical_coordinates>
    <model name='innok_heros'>
      <link name='base_link'>
        <pose>0 0 0 0 -0 0</pose>
        <inertial>
          <pose>0.301893 -0.0011379 -0.0760723 0 -0 0</pose>
          <mass>24.22</mass>
          <inertia>
            <ixx>0.715177</ixx>
            <ixy>-0.00446177</ixy>
            <ixz>-0.166306</ixz>
            <iyy>1.5241</iyy>
            <iyz>-0.00183075</iyz>
            <izz>1.689</izz>
          </inertia>
        </inertial>
        <collision name='base_link_collision'>
          <pose>0.4 0 0.02 0 -0 0</pose>
          <geometry>
            <box>
              <size>0.8 0.16 0.04</size>
            </box>
          </geometry>
          <max_contacts>10</max_contacts>
          <surface>
            <bounce/>
            <friction>
              <ode/>
            </friction>
            <contact>
              <ode/>
            </contact>
          </surface>
        </collision>
        <collision name='base_link_collision_battery_box'>
          <pose>0.398 0 -0.131 0 -0 0</pose>
          <geometry>
            <box>
              <size>0.124 0.328 0.248</size>
            </box>
          </geometry>
          <max_contacts>10</max_contacts>
          <surface>
            <bounce/>
            <friction>
              <ode/>
            </friction>
            <contact>
              <ode/>
            </contact>
          </surface>
        </collision>
        <collision name='base_link_collision_caster_top'>
          <pose>0.717 0 -0.031 0 -0 0</pose>
          <geometry>
            <box>
              <size>0.16 0.16 0.05</size>
            </box>
          </geometry>
          <max_contacts>10</max_contacts>
          <surface>
            <bounce/>
            <friction>
              <ode/>
            </friction>
            <contact>
              <ode/>
            </contact>
          </surface>
        </collision>
        <collision name='base_link_collision_drive_box_rear'>
          <pose>0.16 0 -0.1305 0 -0 0</pose>
          <geometry>
            <box>
              <size>0.284 0.328 0.248</size>
            </box>
          </geometry>
          <max_contacts>10</max_contacts>
          <surface>
            <bounce/>
            <friction>
              <ode/>
            </friction>
            <contact>
              <ode/>
            </contact>
          </surface>
        </collision>
        <collision name='base_link_collision_mounting_plate'>
          <pose>0.44 0 0.048 0 -0 0</pose>
          <geometry>
            <box>
              <size>0.92 0.72 0.004</size>
            </box>
          </geometry>
          <max_contacts>10</max_contacts>
          <surface>
            <bounce/>
            <friction>
              <ode/>
            </friction>
            <contact>
              <ode/>
            </contact>
          </surface>
        </collision>
        <visual name='base_link_visual'>
          <pose>0 0 0 0 -0 0</pose>
          <geometry>
            <mesh>
              <scale>1 1 1</scale>
              <uri>/opt/ros/indigo/share/innok_heros_description/meshes/base_link.STL</uri>
            </mesh>
          </geometry>
        </visual>
        <visual name='base_link_visual_battery_box'>
          <pose>0.336 0 -0.007 0 -0 0</pose>
          <geometry>
            <mesh>
              <scale>1 1 1</scale>
              <uri>/opt/ros/indigo/share/innok_heros_description/meshes/battery_box.STL</uri>
            </mesh>
          </geometry>
        </visual>
        <visual name='base_link_visual_caster_top'>
          <pose>0.637 0 -0.006 0 -0 0</pose>
          <geometry>
            <mesh>
              <scale>1 1 1</scale>
              <uri>/opt/ros/indigo/share/innok_heros_description/meshes/caster_top.STL</uri>
            </mesh>
          </geometry>
        </visual>
        <visual name='base_link_visual_drive_box_rear'>
          <pose>0.018 0 -0.0065 0 -0 0</pose>
          <geometry>
            <mesh>
              <scale>1 1 1</scale>
              <uri>/opt/ros/indigo/share/innok_heros_description/meshes/drive_box.STL</uri>
            </mesh>
          </geometry>
        </visual>
        <visual name='base_link_visual_mounting_plate'>
          <pose>-0.02 0 0.05 0 -0 0</pose>
          <geometry>
            <mesh>
              <scale>1 1 1</scale>
              <uri>/opt/ros/indigo/share/innok_heros_description/meshes/mounting_plate_3w.STL</uri>
            </mesh>
          </geometry>
        </visual>
        <velocity_decay>
          <linear>0</linear>
          <angular>0</angular>
        </velocity_decay>
        <self_collide>0</self_collide>
        <kinematic>0</kinematic>
        <gravity>1</gravity>
      </link>
      <link name='caster_bot'>
        <pose>0.72 0 -0.041 0 -0 0</pose>
        <inertial>
          <pose>-0.023 0 -0.062 0 -0 0</pose>
          <mass>2.9</mass>
          <inertia>
            <ixx>0.016</ixx>
            <ixy>0</ixy>
            <ixz>0.005</ixz>
            <iyy>0.016</iyy>
            <iyz>0</iyz>
            <izz>0.01</izz>
          </inertia>
        </inertial>
        <collision name='caster_bot_collision'>
          <pose>0 0 -0.05 0 -0 0</pose>
          <geometry>
            <cylinder>
              <length>0.09</length>
              <radius>0.07</radius>
            </cylinder>
          </geometry>
          <max_contacts>10</max_contacts>
          <surface>
            <bounce/>
            <friction>
              <ode/>
            </friction>
            <contact>
              <ode/>
            </contact>
          </surface>
        </collision>
        <visual name='caster_bot_visual'>
          <pose>0 0 0 0 -0 0</pose>
          <geometry>
            <mesh>
              <scale>1 1 1</scale>
              <uri>/opt/ros/indigo/share/innok_heros_description/meshes/caster_bot.STL</uri>
            </mesh>
          </geometry>
        </visual>
        <velocity_decay>
          <linear>0</linear>
          <angular>0</angular>
        </velocity_decay>
        <self_collide>0</self_collide>
        <kinematic>0</kinematic>
        <gravity>1</gravity>
      </link>
      <joint name='caster_bot_joint' type='revolute'>
        <child>caster_bot</child>
        <parent>base_link</parent>
        <axis>
          <xyz>0 0 1</xyz>
          <limit>
            <lower>-1e+16</lower>
            <upper>1e+16</upper>
          </limit>
          <dynamics/>
        </axis>
      </joint>
      <link name='caster_wheel'>
        <pose>0.64 -0.014 -0.211 0 -0 0.003</pose>
        <inertial>
          <pose>0 0 0 0 -0 0</pose>
          <mass>5</mass>
          <inertia>
            <ixx>0.017</ixx>
            <ixy>0</ixy>
            <ixz>0</ixz>
            <iyy>0.03</iyy>
            <iyz>0</iyz>
            <izz>0.017</izz>
          </inertia>
        </inertial>
        <collision name='caster_wheel_collision'>
          <pose>0 0.01 0 -1.57 0 0</pose>
          <geometry>
            <cylinder>
              <length>0.085</length>
              <radius>0.125</radius>
            </cylinder>
          </geometry>
          <surface>
            <contact>
              <ode/>
            </contact>
            <friction>
              <ode/>
            </friction>
            <bounce/>
          </surface>
          <max_contacts>10</max_contacts>
        </collision>
        <visual name='caster_wheel_visual'>
          <pose>0 0 0 0 -0 0</pose>
          <geometry>
            <mesh>
              <scale>1 1 1</scale>
              <uri>/opt/ros/indigo/share/innok_heros_description/meshes/caster_wheel.STL</uri>
            </mesh>
          </geometry>
          <material>
            <script>
              <name>Gazebo/Grey</name>
              <uri>__default__</uri>
            </script>
          </material>
        </visual>
        <gravity>1</gravity>
        <velocity_decay>
          <linear>0</linear>
          <angular>0</angular>
        </velocity_decay>
        <self_collide>0</self_collide>
        <kinematic>0</kinematic>
      </link>
      <joint name='caster_wheel_joint' type='revolute'>
        <child>caster_wheel</child>
        <parent>caster_bot</parent>
        <axis>
          <xyz>-0.003 0.999996 0</xyz>
          <limit>
            <lower>-1e+16</lower>
            <upper>1e+16</upper>
          </limit>
          <dynamics/>
        </axis>
      </joint>
      <link name='wheel_rear_left'>
        <pose>0.081 0.162 -0.1905 0 -0 0</pose>
        <inertial>
          <pose>0 0.115 0 0 -0 0</pose>
          <mass>5.4</mass>
          <inertia>
            <ixx>0.046</ixx>
            <ixy>0</ixy>
            <ixz>0</ixz>
            <iyy>0.072</iyy>
            <iyz>0</iyz>
            <izz>0.045</izz>
          </inertia>
        </inertial>
        <collision name='wheel_rear_left_collision'>
          <pose>0 0.115 0 -1.5708 0 0</pose>
          <geometry>
            <cylinder>
              <length>0.16</length>
              <radius>0.16</radius>
            </cylinder>
          </geometry>
          <surface>
            <contact>
              <ode>
                <kp>1e+10</kp>
                <kd>1</kd>
              </ode>
            </contact>
            <friction>
              <ode>
                <mu>5</mu>
                <mu2>5</mu2>
                <fdir1>0 0 1</fdir1>
              </ode>
            </friction>
            <bounce/>
          </surface>
          <max_contacts>10</max_contacts>
        </collision>
        <visual name='wheel_rear_left_visual'>
          <pose>0 0 0 0 -0 0</pose>
          <geometry>
            <mesh>
              <scale>1 1 1</scale>
              <uri>/opt/ros/indigo/share/innok_heros_description/meshes/wheel.STL</uri>
            </mesh>
          </geometry>
          <material>
            <script>
              <name>Gazebo/Grey</name>
              <uri>__default__</uri>
            </script>
          </material>
        </visual>
        <gravity>1</gravity>
        <velocity_decay>
          <linear>0</linear>
          <angular>0</angular>
        </velocity_decay>
        <self_collide>0</self_collide>
        <gravity>1</gravity>
        <kinematic>0</kinematic>
      </link>
      <joint name='joint_base_wheel_rear_left' type='revolute'>
        <child>wheel_rear_left</child>
        <parent>base_link</parent>
        <axis>
          <xyz>0 1 0</xyz>
          <limit>
            <lower>-1e+16</lower>
            <upper>1e+16</upper>
          </limit>
          <dynamics/>
        </axis>
      </joint>
      <link name='wheel_rear_right'>
        <pose>0.081 -0.162 -0.1905 0 -0 -3.14159</pose>
        <inertial>
          <pose>0 0.115 0 0 -0 0</pose>
          <mass>5.4</mass>
          <inertia>
            <ixx>0.046</ixx>
            <ixy>0</ixy>
            <ixz>0</ixz>
            <iyy>0.072</iyy>
            <iyz>0</iyz>
            <izz>0.045</izz>
          </inertia>
        </inertial>
        <collision name='wheel_rear_right_collision'>
          <pose>0 0.115 0 -1.5708 0 0</pose>
          <geometry>
            <cylinder>
              <length>0.16</length>
              <radius>0.16</radius>
            </cylinder>
          </geometry>
          <surface>
            <contact>
              <ode>
                <kp>1e+10</kp>
                <kd>1</kd>
              </ode>
            </contact>
            <friction>
              <ode>
                <mu>5</mu>
                <mu2>5</mu2>
                <fdir1>0 0 1</fdir1>
              </ode>
            </friction>
            <bounce/>
          </surface>
          <max_contacts>10</max_contacts>
        </collision>
        <visual name='wheel_rear_right_visual'>
          <pose>0 0 0 0 -0 0</pose>
          <geometry>
            <mesh>
              <scale>1 1 1</scale>
              <uri>/opt/ros/indigo/share/innok_heros_description/meshes/wheel.STL</uri>
            </mesh>
          </geometry>
          <material>
            <script>
              <name>Gazebo/Grey</name>
              <uri>__default__</uri>
            </script>
          </material>
        </visual>
        <gravity>1</gravity>
        <velocity_decay>
          <linear>0</linear>
          <angular>0</angular>
        </velocity_decay>
        <self_collide>0</self_collide>
        <gravity>1</gravity>
        <kinematic>0</kinematic>
      </link>
      <joint name='joint_base_wheel_rear_right' type='revolute'>
        <child>wheel_rear_right</child>
        <parent>base_link</parent>
        <axis>
          <xyz>-0 1 0</xyz>
          <limit>
            <lower>-1e+16</lower>
            <upper>1e+16</upper>
          </limit>
          <dynamics/>
        </axis>
      </joint>
      <plugin name='joint_state_publisher' filename='libgazebo_ros_joint_state_publisher.so'>
        <robotNamespace>/</robotNamespace>
        <jointName>joint_base_wheel_rear_left, joint_base_wheel_rear_right, caster_bot_joint, caster_wheel_joint</jointName>
        <updateRate>100.0</updateRate>
        <alwaysOn>true</alwaysOn>
      </plugin>
      <static>0</static>
      <plugin name='differential_drive_controller' filename='libgazebo_ros_diff_drive.so'>
        <alwaysOn>true</alwaysOn>
        <updateRate>100</updateRate>
        <leftJoint>joint_base_wheel_rear_right</leftJoint>
        <rightJoint>joint_base_wheel_rear_left</rightJoint>
        <wheelSeparation>0.580</wheelSeparation>
        <wheelDiameter>0.32</wheelDiameter>
        <wheelTorque>130</wheelTorque>
        <commandTopic>cmd_vel</commandTopic>
        <odometryTopic>odom</odometryTopic>
        <robotBaseFrame>base_link</robotBaseFrame>
        <robotNamespace>/</robotNamespace>
      </plugin>
      <pose>0 0 0.5 0 -0 0</pose>
    </model>
    <state world_name='default'>
      <sim_time>1440 107000000</sim_time>
      <real_time>1461 959300683</real_time>
      <wall_time>1728959443 618000002</wall_time>
      <model name='ground_plane'>
        <pose>0 0 0 0 -0 0</pose>
        <link name='link'>
          <pose>0 0 0 0 -0 0</pose>
          <velocity>0 0 0 0 -0 0</velocity>
          <acceleration>0 0 0 0 -0 0</acceleration>
          <wrench>0 0 0 0 -0 0</wrench>
        </link>
      </model>
      <model name='innok_heros'>
        <pose>0.154435 0.002598 0.352539 2.16914e-19 0.025959 0.052579</pose>
        <link name='base_link'>
          <pose>0.154435 0.002598 0.352539 2.16914e-19 0.025959 0.052579</pose>
          <velocity>0.00164 7.5e-05 0.000457 -0.000329 0.007355 6e-06</velocity>
          <acceleration>0 0 0 0 -0 0</acceleration>
          <wrench>0 0 0 0 -0 0</wrench>
        </link>
        <link name='caster_bot'>
          <pose>0.872135 0.040369 0.292864 0.000664 0.025953 0.078185</pose>
          <velocity>0.001126 5.1e-05 -0.004894 -0.000295 0.007134 0.000435</velocity>
          <acceleration>0 0 0 0 -0 0</acceleration>
          <wrench>0 0 0 0 -0 0</wrench>
        </link>
        <link name='caster_wheel'>
          <pose>0.789093 0.019934 0.124988 3.1408 0.369978 -3.06071</pose>
          <velocity>-0.000162 -2.8e-05 -0.004297 -3e-05 0.003043 0.00027</velocity>
          <acceleration>0 0 0 0 -0 0</acceleration>
          <wrench>0 0 0 0 -0 0</wrench>
        </link>
        <link name='wheel_rear_left'>
          <pose>0.221844 0.16837 0.16 -1e-06 0.783858 0.052579</pose>
          <velocity>0.000375 -3e-06 -1.5e-05 -0.000129 0.005094 -0.002211</velocity>
          <acceleration>0 0 0 0 -0 0</acceleration>
          <wrench>0 0 0 0 -0 0</wrench>
        </link>
        <link name='wheel_rear_right'>
          <pose>0.238872 -0.155182 0.16 -2e-06 -0.962791 -3.08901</pose>
          <velocity>0.00037 2.3e-05 -7e-06 -0.000297 0.005192 0.002315</velocity>
          <acceleration>0 0 0 0 -0 0</acceleration>
          <wrench>0 0 0 0 -0 0</wrench>
        </link>
      </model>
    </state>
    <gui fullscreen='0'>
      <camera name='user_camera'>
        <pose>1.68618 -1.31691 0.974596 -1.48488e-17 0.363643 2.36419</pose>
        <view_controller>orbit</view_controller>
      </camera>
    </gui>
  </world>
</sdf>
